test_data/orders.json
{
  "orders": [
    {
      "id": 1,
      "side": "bid",
      "price": 10044,
      "quantity": 48,
      "timestamp": 1700000000000
    },
    {
      "id": 2,
      "side": "ask",
      "price": 10112,
      "quantity": 15,
      "timestamp": 1700000000001
    },
    {
      "id": 3,
      "side": "bid",
      "price": 9862,
      "quantity": 7,
      "timestamp": 1700000000002
    },
    {
      "id": 4,
      "side": "bid",
      "price": 9899,
      "quantity": 28,
      "timestamp": 1700000000003
    },
    {
      "id": 5,
      "side": "bid",
      "price": 10043,
      "quantity": 6,
      "timestamp": 1700000000004
    },
    {
      "id": 6,
      "side": "bid",
      "price": 9991,
      "quantity": 33,
      "timestamp": 1700000000005
    },
    {
      "id": 7,
      "side": "bid",
      "price": 9907,
      "quantity": 13,
      "timestamp": 1700000000006
    },
    {
      "id": 8,
      "side": "ask",
      "price": 10106,
      "quantity": 29,
      "timestamp": 1700000000007
    },
    {
      "id": 9,
      "side": "ask",
      "price": 10051,
      "quantity": 49,
      "timestamp": 1700000000008
    },
    {
      "id": 10,
      "side": "bid",
      "price": 9872,
      "quantity": 28,
      "timestamp": 1700000000009
    },
    {
      "id": 11,
      "side": "ask",
      "price": 10121,
      "quantity": 10,
      "timestamp": 1700000000010
    },
    {
      "id": 12,
      "side": "bid",
      "price": 9855,
      "quantity": 22,
      "timestamp": 1700000000011
    },
    {
      "id": 13,
      "side": "bid",
      "price": 10027,
      "quantity": 25,
      "timestamp": 1700000000012
    },
    {
      "id": 14,
      "side": "bid",
      "price": 9959,
      "quantity": 23,
      "timestamp": 1700000000013
    },
    {
      "id": 15,
      "side": "ask",
      "price": 10061,
      "quantity": 47,
      "timestamp": 1700000000014
    },
    {
      "id": 16,
      "side": "ask",
      "price": 10187,
      "quantity": 8,
      "timestamp": 1700000000015
    },
    {
      "id": 17,
      "side": "ask",
      "price": 10070,
      "quantity": 36,
      "timestamp": 1700000000016
    },
    {
      "id": 18,
      "side": "ask",
      "price": 10210,
      "quantity": 40,
      "timestamp": 1700000000017
    },
    {
      "id": 19,
      "side": "ask",
      "price": 10197,
      "quantity": 13,
      "timestamp": 1700000000018
    },
    {
      "id": 20,
      "side": "bid",
      "price": 10039,
      "quantity": 43,
      "timestamp": 1700000000019
    },
    {
      "id": 21,
      "side": "bid",
      "price": 9853,
      "quantity": 19,
      "timestamp": 1700000000020
    },
    {
      "id": 22,
      "side": "bid",
      "price": 9991,
      "quantity": 7,
      "timestamp": 1700000000021
    },
    {
      "id": 23,
      "side": "ask",
      "price": 10121,
      "quantity": 30,
      "timestamp": 1700000000022
    },
    {
      "id": 24,
      "side": "ask",
      "price": 10091,
      "quantity": 24,
      "timestamp": 1700000000023
    },
    {
      "id": 25,
      "side": "ask",
      "price": 10103,
      "quantity": 43,
      "timestamp": 1700000000024
    },
    {
      "id": 26,
      "side": "ask",
      "price": 10229,
      "quantity": 44,
      "timestamp": 1700000000025
    },
    {
      "id": 27,
      "side": "bid",
      "price": 9895,
      "quantity": 41,
      "timestamp": 1700000000026
    },
    {
      "id": 28,
      "side": "bid",
      "price": 9914,
      "quantity": 47,
      "timestamp": 1700000000027
    },
    {
      "id": 29,
      "side": "bid",
      "price": 10009,
      "quantity": 30,
      "timestamp": 1700000000028
    },
    {
      "id": 30,
      "side": "ask",
      "price": 10119,
      "quantity": 41,
      "timestamp": 1700000000029
    },
    {
      "id": 31,
      "side": "bid",
      "price": 9875,
      "quantity": 21,
      "timestamp": 1700000000030
    },
    {
      "id": 32,
      "side": "bid",
      "price": 9992,
      "quantity": 3,
      "timestamp": 1700000000031
    },
    {
      "id": 33,
      "side": "ask",
      "price": 10152,
      "quantity": 18,
      "timestamp": 1700000000032
    },
    {
      "id": 34,
      "side": "bid",
      "price": 9996,
      "quantity": 37,
      "timestamp": 1700000000033
    },
    {
      "id": 35,
      "side": "ask",
      "price": 10104,
      "quantity": 42,
      "timestamp": 1700000000034
    },
    {
      "id": 36,
      "side": "ask",
      "price": 10151,
      "quantity": 42,
      "timestamp": 1700000000035
    },
    {
      "id": 37,
      "side": "ask",
      "price": 10086,
      "quantity": 17,
      "timestamp": 1700000000036
    },
    {
      "id": 38,
      "side": "bid",
      "price": 9987,
      "quantity": 48,
      "timestamp": 1700000000037
    },
    {
      "id": 39,
      "side": "ask",
      "price": 10241,
      "quantity": 38,
      "timestamp": 1700000000038
    },
    {
      "id": 40,
      "side": "ask",
      "price": 10199,
      "quantity": 26,
      "timestamp": 1700000000039
    },
    {
      "id": 41,
      "side": "ask",
      "price": 10106,
      "quantity": 9,
      "timestamp": 1700000000040
    },
    {
      "id": 42,
      "side": "ask",
      "price": 10073,
      "quantity": 49,
      "timestamp": 1700000000041
    },
    {
      "id": 43,
      "side": "bid",
      "price": 10022,
      "quantity": 10,
      "timestamp": 1700000000042
    },
    {
      "id": 44,
      "side": "bid",
      "price": 9876,
      "quantity": 28,
      "timestamp": 1700000000043
    },
    {
      "id": 45,
      "side": "bid",
      "price": 9952,
      "quantity": 25,
      "timestamp": 1700000000044
    },
    {
      "id": 46,
      "side": "ask",
      "price": 10185,
      "quantity": 17,
      "timestamp": 1700000000045
    },
    {
      "id": 47,
      "side": "bid",
      "price": 9876,
      "quantity": 47,
      "timestamp": 1700000000046
    },
    {
      "id": 48,
      "side": "bid",
      "price": 9876,
      "quantity": 35,
      "timestamp": 1700000000047
    },
    {
      "id": 49,
      "side": "ask",
      "price": 10246,
      "quantity": 42,
      "timestamp": 1700000000048
    },
    {
      "id": 50,
      "side": "ask",
      "price": 10078,
      "quantity": 19,
      "timestamp": 1700000000049
    },
    {
      "id": 51,
      "side": "ask",
      "price": 10090,
      "quantity": 30,
      "timestamp": 1700000000050
    },
    {
      "id": 52,
      "side": "bid",
      "price": 9866,
      "quantity": 47,
      "timestamp": 1700000000051
    },
    {
      "id": 53,
      "side": "ask",
      "price": 10178,
      "quantity": 49,
      "timestamp": 1700000000052
    },
    {
      "id": 54,
      "side": "bid",
      "price": 9921,
      "quantity": 7,
      "timestamp": 1700000000053
    },
    {
      "id": 55,
      "side": "ask",
      "price": 10213,
      "quantity": 33,
      "timestamp": 1700000000054
    },
    {
      "id": 56,
      "side": "bid",
      "price": 10011,
      "quantity": 24,
      "timestamp": 1700000000055
    },
    {
      "id": 57,
      "side": "bid",
      "price": 9912,
      "quantity": 50,
      "timestamp": 1700000000056
    },
    {
      "id": 58,
      "side": "bid",
      "price": 9897,
      "quantity": 21,
      "timestamp": 1700000000057
    },
    {
      "id": 59,
      "side": "ask",
      "price": 10054,
      "quantity": 8,
      "timestamp": 1700000000058
    },
    {
      "id": 60,
      "side": "ask",
      "price": 10128,
      "quantity": 16,
      "timestamp": 1700000000059
    },
    {
      "id": 61,
      "side": "bid",
      "price": 9989,
      "quantity": 37,
      "timestamp": 1700000000060
    },
    {
      "id": 62,
      "side": "bid",
      "price": 10029,
      "quantity": 47,
      "timestamp": 1700000000061
    },
    {
      "id": 63,
      "side": "ask",
      "price": 10067,
      "quantity": 49,
      "timestamp": 1700000000062
    },
    {
      "id": 64,
      "side": "bid",
