test_data/orders_large_matched.json
{
  "orders": [
    {
      "id": 1,
      "side": "ask",
      "price": 10003,
      "quantity": 13,
      "timestamp": 1700000000000
    },
    {
      "id": 2,
      "side": "bid",
      "price": 10028,
      "quantity": 13,
      "timestamp": 1700000000001
    },
    {
      "id": 3,
      "side": "ask",
      "price": 10053,
      "quantity": 6,
      "timestamp": 1700000000002
    },
    {
      "id": 4,
      "side": "bid",
      "price": 10082,
      "quantity": 6,
      "timestamp": 1700000000003
    },
    {
      "id": 5,
      "side": "ask",
      "price": 9963,
      "quantity": 5,
      "timestamp": 1700000000004
    },
    {
      "id": 6,
      "side": "bid",
      "price": 10060,
      "quantity": 5,
      "timestamp": 1700000000005
    },
    {
      "id": 7,
      "side": "ask",
      "price": 9922,
      "quantity": 9,
      "timestamp": 1700000000006
    },
    {
      "id": 8,
      "side": "bid",
      "price": 10015,
      "quantity": 9,
      "timestamp": 1700000000007
    },
    {
      "id": 9,
      "side": "ask",
      "price": 9998,
      "quantity": 17,
      "timestamp": 1700000000008
    },
    {
      "id": 10,
      "side": "bid",
      "price": 10085,
      "quantity": 17,
      "timestamp": 1700000000009
    },
    {
      "id": 11,
      "side": "ask",
      "price": 10079,
      "quantity": 18,
      "timestamp": 1700000000010
    },
    {
      "id": 12,
      "side": "bid",
      "price": 10090,
      "quantity": 18,
      "timestamp": 1700000000011
    },
    {
      "id": 13,
      "side": "ask",
      "price": 10059,
      "quantity": 16,
      "timestamp": 1700000000012
    },
    {
      "id": 14,
      "side": "bid",
      "price": 10084,
      "quantity": 16,
      "timestamp": 1700000000013
    },
    {
      "id": 15,
      "side": "ask",
      "price": 10007,
      "quantity": 20,
      "timestamp": 1700000000014
    },
    {
      "id": 16,
      "side": "bid",
      "price": 10082,
      "quantity": 20,
      "timestamp": 1700000000015
    },
    {
      "id": 17,
      "side": "ask",
      "price": 9955,
      "quantity": 12,
      "timestamp": 1700000000016
    },
    {
      "id": 18,
      "side": "bid",
      "price": 10004,
      "quantity": 12,
      "timestamp": 1700000000017
    },
    {
      "id": 19,
      "side": "ask",
      "price": 10074,
      "quantity": 7,
      "timestamp": 1700000000018
    },
    {
      "id": 20,
      "side": "bid",
      "price": 10093,
      "quantity": 7,
      "timestamp": 1700000000019
    },
    {
      "id": 21,
      "side": "ask",
      "price": 10018,
      "quantity": 6,
      "timestamp": 1700000000020
    },
    {
      "id": 22,
      "side": "bid",
      "price": 10090,
      "quantity": 6,
      "timestamp": 1700000000021
    },
    {
      "id": 23,
      "side": "ask",
      "price": 9986,
      "quantity": 3,
      "timestamp": 1700000000022
    },
    {
      "id": 24,
      "side": "bid",
      "price": 10077,
      "quantity": 3,
      "timestamp": 1700000000023
    },
    {
      "id": 25,
      "side": "ask",
      "price": 10035,
      "quantity": 3,
      "timestamp": 1700000000024
    },
    {
      "id": 26,
      "side": "bid",
      "price": 10095,
      "quantity": 3,
      "timestamp": 1700000000025
    },
    {
      "id": 27,
      "side": "ask",
      "price": 9980,
      "quantity": 13,
      "timestamp": 1700000000026
    },
    {
      "id": 28,
      "side": "bid",
      "price": 9985,
      "quantity": 13,
      "timestamp": 1700000000027
    },
    {
      "id": 29,
      "side": "ask",
      "price": 9968,
      "quantity": 18,
      "timestamp": 1700000000028
    },
    {
      "id": 30,
      "side": "bid",
      "price": 9968,
      "quantity": 18,
      "timestamp": 1700000000029
    },
    {
      "id": 31,
      "side": "ask",
      "price": 10008,
      "quantity": 7,
      "timestamp": 1700000000030
    },
    {
      "id": 32,
      "side": "bid",
      "price": 10054,
      "quantity": 7,
      "timestamp": 1700000000031
    },
    {
      "id": 33,
      "side": "ask",
      "price": 10036,
      "quantity": 3,
      "timestamp": 1700000000032
    },
    {
      "id": 34,
      "side": "bid",
      "price": 10095,
      "quantity": 3,
      "timestamp": 1700000000033
    },
    {
      "id": 35,
      "side": "ask",
      "price": 10032,
      "quantity": 7,
      "timestamp": 1700000000034
    },
    {
      "id": 36,
      "side": "bid",
      "price": 10109,
      "quantity": 7,
      "timestamp": 1700000000035
    },
    {
      "id": 37,
      "side": "ask",
      "price": 10018,
      "quantity": 2,
      "timestamp": 1700000000036
    },
    {
      "id": 38,
      "side": "bid",
      "price": 10063,
      "quantity": 2,
      "timestamp": 1700000000037
    },
    {
      "id": 39,
      "side": "ask",
      "price": 9933,
      "quantity": 7,
      "timestamp": 1700000000038
    },
    {
      "id": 40,
      "side": "bid",
      "price": 10024,
      "quantity": 7,
      "timestamp": 1700000000039
    },
    {
      "id": 41,
      "side": "ask",
      "price": 9841,
      "quantity": 6,
      "timestamp": 1700000000040
    },
    {
      "id": 42,
      "side": "ask",
      "price": 9851,
      "quantity": 3,
      "timestamp": 1700000000041
    },
    {
      "id": 43,
      "side": "ask",
      "price": 9861,
      "quantity": 6,
      "timestamp": 1700000000042
    },
    {
      "id": 44,
      "side": "ask",
      "price": 9871,
      "quantity": 7,
      "timestamp": 1700000000043
    },
    {
      "id": 45,
      "side": "ask",
      "price": 9881,
      "quantity": 3,
      "timestamp": 1700000000044
    },
    {
      "id": 46,
      "side": "bid",
      "price": 9941,
      "quantity": 25,
      "timestamp": 1700000000045
    },
    {
      "id": 47,
      "side": "ask",
      "price": 9809,
      "quantity": 2,
      "timestamp": 1700000000046
    },
    {
      "id": 48,
      "side": "ask",
      "price": 9819,
      "quantity": 3,
      "timestamp": 1700000000047
    },
    {
      "id": 49,
      "side": "bid",
      "price": 9879,
      "quantity": 5,
      "timestamp": 1700000000048
    },
    {
      "id": 50,
      "side": "ask",
      "price": 9921,
      "quantity": 2,
      "timestamp": 1700000000049
    },
    {
      "id": 51,
      "side": "ask",
      "price": 9931,
      "quantity": 5,
      "timestamp": 1700000000050
    },
    {
      "id": 52,
      "side": "ask",
      "price": 9941,
      "quantity": 7,
      "timestamp": 1700000000051
    },
    {
      "id": 53,
      "side": "ask",
      "price": 9951,
      "quantity": 2,
      "timestamp": 1700000000052
    },
    {
      "id": 54,
      "side": "ask",
      "price": 9961,
      "quantity": 3,
      "timestamp": 1700000000053
    },
    {
      "id": 55,
      "side": "bid",
      "price": 10021,
      "quantity": 19,
      "timestamp": 1700000000054
    },
    {
      "id": 56,
      "side": "ask",
      "price": 9879,
      "quantity": 5,
      "timestamp": 1700000000055
    },
    {
      "id": 57,
      "side": "ask",
      "price": 9889,
      "quantity": 4,
      "timestamp": 1700000000056
    },
    {
      "id": 58,
      "side": "bid",
      "price": 9949,
      "quantity": 9,
      "timestamp": 1700000000057
    },
    {
      "id": 59,
      "side": "ask",
      "price": 9834,
      "quantity": 3,
      "timestamp": 1700000000058
    },
    {
      "id": 60,
      "side": "ask",
      "price": 9844,
      "quantity": 8,
      "timestamp": 1700000000059
    },
    {
      "id": 61,
      "side": "ask",
      "price": 9854,
      "quantity": 2,
      "timestamp": 1700000000060
    },
    {
      "id": 62,
      "side": "ask",
      "price": 9864,
      "quantity": 7,
      "timestamp": 1700000000061
    },
    {
      "id": 63,
      "side": "ask",
      "price": 9874,
      "quantity": 3,
      "timestamp": 1700000000062
    },
    {
      "id": 64,
      "side": "bid",
      "price": 9934,
      "quantity": 23,
