test_data/orders_matched.json
{
  "orders": [
    { "id": 1, "side": "ask", "price": 10000, "quantity": 5, "timestamp": 1700000000001 },
    { "id": 2, "side": "bid", "price": 10100, "quantity": 5, "timestamp": 1700000000002 },

    { "id": 3, "side": "ask", "price": 9900, "quantity": 10, "timestamp": 1700000000003 },
    { "id": 4, "side": "bid", "price": 10000, "quantity": 10, "timestamp": 1700000000004 },

    { "id": 5, "side": "ask", "price": 10050, "quantity": 3, "timestamp": 1700000000005 },
    { "id": 6, "side": "bid", "price": 10200, "quantity": 3, "timestamp": 1700000000006 },

    { "id": 7,  "side": "ask", "price": 9800, "quantity": 4,  "timestamp": 1700000000007 },
    { "id": 8,  "side": "ask", "price": 9850, "quantity": 6,  "timestamp": 1700000000008 },
    { "id": 9,  "side": "ask", "price": 9900, "quantity": 5,  "timestamp": 1700000000009 },
    { "id": 10, "side": "bid", "price": 10000, "quantity": 15, "timestamp": 1700000000010 },

    { "id": 11, "side": "bid", "price": 10100, "quantity": 4,  "timestamp": 1700000000011 },
    { "id": 12, "side": "bid", "price": 10050, "quantity": 6,  "timestamp": 1700000000012 },
    { "id": 13, "side": "bid", "price": 10000, "quantity": 5,  "timestamp": 1700000000013 },
    { "id": 14, "side": "ask", "price": 9900,  "quantity": 15, "timestamp": 1700000000014 },

    { "id": 15, "side": "ask", "price": 9900, "quantity": 20, "timestamp": 1700000000015 },
    { "id": 16, "side": "bid", "price": 9950, "quantity": 8,  "timestamp": 1700000000016 },
    { "id": 17, "side": "bid", "price": 9950, "quantity": 7,  "timestamp": 1700000000017 },
    { "id": 18, "side": "bid", "price": 9950, "quantity": 5,  "timestamp": 1700000000018 },

    { "id": 19, "side": "ask", "price": 10000, "quantity": 5, "timestamp": 1700000000019 },
    { "id": 20, "side": "bid", "price": 10000, "quantity": 5, "timestamp": 1700000000020 },

    { "id": 21, "side": "ask", "price": 9750, "quantity": 3, "timestamp": 1700000000021 },
    { "id": 22, "side": "bid", "price": 9750, "quantity": 3, "timestamp": 1700000000022 },

    { "id": 23, "side": "ask", "price": 9800, "quantity": 10, "timestamp": 1700000000023 },
    { "id": 24, "side": "bid", "price": 10000, "quantity": 3,  "timestamp": 1700000000024 },
    { "id": 25, "side": "bid", "price": 10000, "quantity": 3,  "timestamp": 1700000000025 },
    { "id": 26, "side": "bid", "price": 10000, "quantity": 4,  "timestamp": 1700000000026 },

    { "id": 27, "side": "ask", "price": 9900, "quantity": 50, "timestamp": 1700000000027 },
    { "id": 28, "side": "bid", "price": 9950, "quantity": 10, "timestamp": 1700000000028 },
    { "id": 29, "side": "bid", "price": 9950, "quantity": 10, "timestamp": 1700000000029 },
    { "id": 30, "side": "bid", "price": 9950, "quantity": 10, "timestamp": 1700000000030 },
    { "id": 31, "side": "bid", "price": 9950, "quantity": 10, "timestamp": 1700000000031 },
    { "id": 32, "side": "bid", "price": 9950, "quantity": 10, "timestamp": 1700000000032 }
  ]
}
